Workbook
Name Ageing_Day_s: 'Inbound data'!$P$9:$P$1500
Name Ageing_Remarks: 'Inbound data'!$Q$9:$Q$1500
Name CLM: 'Inbound data'!$AB$9:$AB$1500
Name CONTAINER_NUMBER: 'Outbound data'!$Q$4:$Q$1480
Name CONTAINER_NUMBER__OUT: 'Outbound data'!$Q$4:$Q$1480
Name Container_Van_No.: 'Inbound data'!$M$9:$M$1500
Name DATE: 'Outbound data'!$B$4:$B$1480
Name Date_Inbound: 'Inbound data'!$D$9:$D$1500
Name DESTINATION: 'Outbound data'!$D$4:$D$1480
Name ENCODED_BY: 'Outbound data'!$J$4:$J$1480
Name Encoder: 'Inbound data'!$Y$9:$Y$1500
Name ENDING_KILOS4: 'Inbound data'!#REF!
Name Ending_Pallet_Quantity: 'Inbound data'!$V$9:$V$1500
Name ENDING_QTY3: 'Inbound data'!#REF!
Name Ending_Quantity: 'Inbound data'!$T$9:$T$1500
Name Ending_Weight: 'Inbound data'!$U$9:$U$1500
Name Expiration_Date: 'Inbound data'!$O$9:$O$1500
Name From_Location: 'Inbound data'!$AF$9:$AF$1500
Name FRZ: 'Inbound data'!$AA$9:$AA$1500
Name GATEPASS: 'Outbound data'!$K$4:$K$1480
Name Gatepass: 'Inbound data'!$I$9:$I$1500
Name Generated_Stockcode: 'Inbound data'!$C$9:$C$1500
Name In_Quantity: 'Inbound data'!$R$9:$R$1500
Name In_Weight: 'Inbound data'!$S$9:$S$1500
Name Inventory_Status: 'Inbound data'!$A$9:$A$1500
Name ITEM_DESCRIPTION: 'Outbound data'!$O$4:$O$1480
Name Item_Description: 'Inbound data'!$L$9:$L$1500
Name ITEM_DESCRIPTION__OUT: 'Outbound data'!$O$4:$O$1480
Name KILOS: 'Outbound data'!$G$4:$G$1480
Name KILOS_OUT: 'Outbound data'!$G$4:$G$1480
Name Location: 'Inbound data'!$AG$9:$AG$1500
Name LVL: 'Inbound data'!$AD$9:$AD$1500
Name Mode_of_Inbound: 'Inbound data'!$E$9:$E$1500
Name No.: 'Inbound data'!$B$9:$B$1500
Name OUT_REMARKS: 'Outbound data'!$M$4:$M$1480
Name OUTBOUND_DATE: 'Outbound data'!$B$4:$B$1480
Name Pallet: 'Inbound data'!$J$9:$J$1500
Name PALLET_COUNT5: 'Inbound data'!#REF!
Name PALLET_NUMBER: 'Outbound data'!$N$4:$N$1480
Name PALLET_NUMBER__OUT: 'Outbound data'!$N$4:$N$1480
Name PALLET_OUT: 'Outbound data'!$H$4:$H$1480
Name Pallet_qty: 'Inbound data'!$K$9:$K$1500
Name Pallet_Qty_In: 'Inbound data'!$K$9:$K$1500
Name Pallet_Series: 'Inbound data'!$J$9:$J$1500
Name PALLET_SERIES__OUT: 'Outbound data'!$N$4:$N$1480
Name PICKLIST: 'Outbound data'!$I$4:$I$1480
Name PLATE: 'Outbound data'!$L$4:$L$1480
Name Production_Date: 'Inbound data'!$N$9:$N$1500
Name QTY_OUT: 'Outbound data'!$F$4:$F$1480
Name Receiving_Report_ref.: 'Inbound data'!$F$9:$F$1500
Name REMARKS: 'Outbound data'!$M$4:$M$1480
Name RW: 'Inbound data'!$AC$9:$AC$1500
Name SIDE: 'Inbound data'!$AE$9:$AE$1500
Name Slicer_Inventory_Status: #N/A
Name Source: 'Inbound data'!$G$9:$G$1500
Name STOCK_CODE: 'Outbound data'!$E$4:$E$1480
Name STOCK_CODE_OUT: 'Outbound data'!$E$4:$E$1480
Name Stock_Remarks: 'Inbound data'!$Z$9:$Z$1500
Name Truck_No.: 'Inbound data'!$H$9:$H$1500
Name UOM: 'Inbound data'!$W$9:$W$1500

Sheet Summary
A1: ='Inbound data'!$D$3 -> Duopower Foods Inc.
A2: Inventory Status | B2: INV
A3: =NOW() -> 46111.157
A4: Row Labels | B4: Container Van No. | C4: Quantity | D4: Weight
A5: PORK/CHICKEN/BEEF/SHRIMP SIOMAI 30'S 500G (APRUB) | B5: LOCAL TRANSFER | C5: 60 | D5: 720
A6: ASADO SIOPAO JUMBO | B6: LOCAL TRANSFER | C6: 25 | D6: 11.8
A7: RED BEAN PAO MINI | B7: LOCAL TRANSFER | C7: 30 | D7: 41.112
A8: CHOCO PAO MINI | B8: LOCAL TRANSFER | C8: 30 | D8: 41.112
A9: ASADO SIOPAO MINI (APRUB) | B9: LOCAL TRANSFER | C9: 100 | D9: 57.44
A10: CHOCO PAO MINI (APRUB) | B10: LOCAL TRANSFER | C10: 50 | D10: 16.08
A11: MINI UBE PAO (APRUB) | B11: LOCAL TRANSFER | C11: 25 | D11: 0.312
A12: RED BEAN PAO MINI (APRUB) | B12: LOCAL TRANSFER | C12: 50 | D12: 16.28
A13: UBE PAO MINI (APRUB) | B13: LOCAL TRANSFER | C13: 75 | D13: 16.992
A14: ASADO SIOPAO JUMBO (APRUB) | B14: LOCAL TRANSFER | C14: 75 | D14: 35.4
A15: CHICKEN ASADO SIOPAO JUMBO (APRUB) | B15: LOCAL TRANSFER | C15: 100 | D15: 47.36
A16: CHICKEN ASADO SIOPAO MINI (APRUB) | B16: LOCAL TRANSFER | C16: 100 | D16: 56.64
... A20: BEEF SIOMAI 30'S 500G | B20: LOCAL TRANSFER | C20: 50 | D20: 600
A21: Grand Total | C21: 820 | D21: 2260.528

Sheet Stocks Inquiry
A1: `=SORT(CHOOSECOLS(FILTER(inbound_data,ISNUMBER(SEARCH($A$12,Item_Description))*ISNUMBER(SEARCH($A$14,Container_Van_No.))*ISNUMBER(SEARCH($A$10,Pallet_Series)),""),4,6,13,12,3,10,14,15,20,21,23,33,26),8,1)
B2: Item Description | D2: Inventory Status | E2: INV
B4: Container Van No. | D4: Sort by:
B6: Pallet Series
J7: =SUBTOTAL(9,J9:J500) -> 30 | K7: =SUBTOTAL(9,K9:K500) -> 48.94 | L7: =SUBTOTAL(9,L9:L500) -> 2
B8: Date Inbound | C8: Receiving Report No. | D8: Container Van No. | E8: Stock Code | F8: Item Description | G8: Pallet # / Pallet Series | H8: Production Date | I8: Expiry Date | J8: Balance Quantity | K8: Balance Weight | L8: Pallet qty | M8: UOM | N8: Location | O8: Stock Remarks
A9: Pallet # / Pallet Series | B9: {=_xlfn._xlws.SORT(_xlfn.CHOOSECOLS(_xlfn._xlws.FILTER(inbound_data[],ISNUMBER(SEARCH($A$12,Item_Description))*ISNUMBER(SEARCH($A$14,Container_Van_No.))*ISNUMBER(SEARCH($A$10,Pallet_Series))*ISNUMBER(SEARCH(E2,Inventory_Status)),""),4,6,13,3,12,10,14,15,20,21,22,23,33,26),$A$21,1)} -> 46098 | C9: 121180 | D9: LOCAL TRANSFER | E9: DUO-00106AB/145700135 | F9: RED BEAN PAO MINI (APRUB) | G9: DUO-00106AB/1457 | H9: 46082 | I9: 46631 | J9: 25 | K9: 8.14 | L9: 1 | M9: BXS | N9: R00L0.0 | O9: 0
A10: 106 | B10: 46106 | C10: 122242 | D10: LOCAL TRANSFER | E10: DUO-00106AC/145700143 | F10: RED BEAN PAO MINI | G10: DUO-00106AC/1457 | H10: 46082 | I10: 46631 | J10: 5 | K10: 40.8 | L10: 1 | M10: BXS | N10: R00L0.0 | O10: 0
A11: Item Description
A13: Container Van No.
A16: lowest to highest
A17: 1
A18: highest to lowest
A19: -1
A20: Sorting Manner
A21: =IF(E4="Available Balance",9,IF(E4="Expiration date",8,IF(E4="Location",13,1))) -> 1

Sheet Outbound data
B1: OUTBOUND LOG
F2: =SUBTOTAL(9,QTY_OUT) -> 4582 | G2: =SUBTOTAL(9,KILOS_OUT) -> 35281.184 | H2: =SUBTOTAL(9,PALLET_OUT) -> 106
B3: OUTBOUND DATE | C3: Withdrawal Report No. | D3: DESTINATION | E3: STOCK CODE OUT | F3: QTY OUT | G3: KILOS OUT | H3: PALLET OUT | I3: PICKLIST | J3: ENCODED BY: | K3: GATEPASS | L3: PLATE # | M3: OUT REMARKS | N3: PALLET SERIES (OUT) | O3: ITEM DESCRIPTION (OUT) | P3: UOM (OUT) | Q3: CONTAINER NUMBER (OUT)
B4: 45912 | C4: 124175 | D4: PASIG | E4: DUO-00001A/633200009 | F4: 70 | G4: 262.08 | H4: 1 | I4: 87920 | J4: IMEE | K4: 73339 | L4: CCK-8782 | N4: =IF(ISBLANK(C4),"",_xlfn.IFNA(INDEX(inbound_data[],MATCH(Outbound_data[[#This Row],[STOCK CODE OUT]],Generated_Stockcode,0),10),"")) -> DUO-00001A/6332 | O4: =IF(ISBLANK(C4),"",_xlfn.IFNA(INDEX(inbound_data[],MATCH(Outbound_data[[#This Row],[STOCK CODE OUT]],Generated_Stockcode,0),12),"")) -> MINIS ASADO 6'S X12 (APRUB) | P4: =IF(ISBLANK(C4),"",_xlfn.IFNA(INDEX(inbound_data[],MATCH(Outbound_data[[#This Row],[STOCK CODE OUT]],Generated_Stockcode,0),23),"")) -> BXS | Q4: =IF(ISBLANK(C4),"",_xlfn.IFNA(INDEX(inbound_data[],MATCH(Outbound_data[[#This Row],[STOCK CODE OUT]],Generated_Stockcode,0),13),"")) -> LOCAL TRANSFER
B5: 45912 | C5: 124175 | D5: PASIG | E5: DUO-00002A/154300010 | F5: 70 | G5: 262.08 | H5: 1 | I5: 87920 | J5: IMEE | K5: 73339 | L5: CCK-8782 | N5: =IF(ISBLANK(C5),"",_xlfn.IFNA(INDEX(inbound_data[],MATCH(Outbound_data[[#This Row],[STOCK CODE OUT]],Generated_Stockcode,0),10),"")) -> DUO-00002A/1543 | O5: =IF(ISBLANK(C5),"",_xlfn.IFNA(INDEX(inbound_data[],MATCH(Outbound_data[[#This Row],[STOCK CODE OUT]],Generated_Stockcode,0),12),"")) -> MINIS ASADO 6'S X12 (APRUB) | P5: =IF(ISBLANK(C5),"",_xlfn.IFNA(INDEX(inbound_data[],MATCH(Outbound_data[[#This Row],[STOCK CODE OUT]],Generated_Stockcode,0),23),"")) -> BXS | Q5: =IF(ISBLANK(C5),"",_xlfn.IFNA(INDEX(inbound_data[],MATCH(Outbound_data[[#This Row],[STOCK CODE OUT]],Generated_Stockcode,0),13),"")) -> LOCAL TRANSFER
B6: 45912 | C6: 124175 | D6: PASIG | E6: DUO-00003A/500700011 | F6: 70 | G6: 262.08 | H6: 1 | I6: 87920 | J6: IMEE | K6: 73339 | L6: CCK-8782 | N6: =IF(ISBLANK(C6),"",_xlfn.IFNA(INDEX(inbound_data[],MATCH(Outbound_data[[#This Row],[STOCK CODE OUT]],Generated_Stockcode,0),10),"")) -> DUO-00003A/5007 | O6: =IF(ISBLANK(C6),"",_xlfn.IFNA(INDEX(inbound_data[],MATCH(Outbound_data[[#This Row],[STOCK CODE OUT]],Generated_Stockcode,0),12),"")) -> MINIS ASADO 6'S X12 (APRUB) | P6: =IF(ISBLANK(C6),"",_xlfn.IFNA(INDEX(inbound_data[],MATCH(Outbound_data[[#This Row],[STOCK CODE OUT]],Generated_Stockcode,0),23),"")) -> BXS | Q6: =IF(ISBLANK(C6),"",_xlfn.IFNA(INDEX(inbound_data[],MATCH(Outbound_data[[#This Row],[STOCK CODE OUT]],Generated_Stockcode,0),13),"")) -> LOCAL TRANSFER
B7: 45912 | C7: 124175 | D7: PASIG | E7: DUO-00010A/4092100018 | F7: 41 | G7: 153.504 | H7: 1 | I7: 87920 | J7: IMEE | K7: 73339 | L7: CCK-8782 | N7: =IF(ISBLANK(C7),"",_xlfn.IFNA(INDEX(inbound_data[],MATCH(Outbound_data[[#This Row],[STOCK CODE OUT]],Generated_Stockcode,0),10),"")) -> DUO-00010A/40921 | O7: =IF(ISBLANK(C7),"",_xlfn.IFNA(INDEX(inbound_data[],MATCH(Outbound_data[[#This Row],[STOCK CODE OUT]],Generated_Stockcode,0),12),"")) -> MINIS ASADO 6'S X12 (APRUB) | P7: =IF(ISBLANK(C7),"",_xlfn.IFNA(INDEX(inbound_data[],MATCH(Outbound_data[[#This Row],[STOCK CODE OUT]],Generated_Stockcode,0),23),"")) -> BXS | Q7: =IF(ISBLANK(C7),"",_xlfn.IFNA(INDEX(inbound_data[],MATCH(Outbound_data[[#This Row],[STOCK CODE OUT]],Generated_Stockcode,0),13),"")) -> LOCAL TRANSFER
B8: 45913 | C8: 126076 | D8: CALOOCAN | E8: DUO-00005A/4182800013 | F8: 70 | G8: 262.08 | H8: 1 | I8: 91909 | J8: IMEE | K8: 74571 | L8: NGN-7085 | N8: =IF(ISBLANK(C8),"",_xlfn.IFNA(INDEX(inbound_data[],MATCH(Outbound_data[[#This Row],[STOCK CODE OUT]],Generated_Stockcode,0),10),"")) -> DUO-00005A/41828 | O8: =IF(ISBLANK(C8),"",_xlfn.IFNA(INDEX(inbound_data[],MATCH(Outbound_data[[#This Row],[STOCK CODE OUT]],Generated_Stockcode,0),12),"")) -> MINIS ASADO 6'S X12 (APRUB) | P8: =IF(ISBLANK(C8),"",_xlfn.IFNA(INDEX(inbound_data[],MATCH(Outbound_data[[#This Row],[STOCK CODE OUT]],Generated_Stockcode,0),23),"")) -> BXS | Q8: =IF(ISBLANK(C8),"",_xlfn.IFNA(INDEX(inbound_data[],MATCH(Outbound_data[[#This Row],[STOCK CODE OUT]],Generated_Stockcode,0),13),"")) -> LOCAL TRANSFER
B9: 45913 | C9: 126076 | D9: CALOOCAN | E9: DUO-00004A/NP00012 | F9: 70 | G9: 262.08 | H9: 1 | I9: 91909 | J9: IMEE | K9: 74571 | L9: NGN-7085 | N9: =IF(ISBLANK(C9),"",_xlfn.IFNA(INDEX(inbound_data[],MATCH(Outbound_data[[#This Row],[STOCK CODE OUT]],Generated_Stockcode,0),10),"")) -> DUO-00004A/NP | O9: =IF(ISBLANK(C9),"",_xlfn.IFNA(INDEX(inbound_data[],MATCH(Outbound_data[[#This Row],[STOCK CODE OUT]],Generated_Stockcode,0),12),"")) -> MINIS ASADO 6'S X12 (APRUB) | P9: =IF(ISBLANK(C9),"",_xlfn.IFNA(INDEX(inbound_data[],MATCH(Outbound_data[[#This Row],[STOCK CODE OUT]],Generated_Stockcode,0),23),"")) -> BXS | Q9: =IF(ISBLANK(C9),"",_xlfn.IFNA(INDEX(inbound_data[],MATCH(Outbound_data[[#This Row],[STOCK CODE OUT]],Generated_Stockcode,0),13),"")) -> LOCAL TRANSFER
B10: 45913 | C10: 126076 | D10: CALOOCAN | E10: DUO-00009A/4034100017 | F10: 70 | G10: 262.08 | H10: 1 | I10: 91909 | J10: IMEE | K10: 74571 | L10: NGN-7085 | N10: =IF(ISBLANK(C10),"",_xlfn.IFNA(INDEX(inbound_data[],MATCH(Outbound_data[[#This Row],[STOCK CODE OUT]],Generated_Stockcode,0),10),"")) -> DUO-00009A/40341 | O10: =IF(ISBLANK(C10),"",_xlfn.IFNA(INDEX(inbound_data[],MATCH(Outbound_data[[#This Row],[STOCK CODE OUT]],Generated_Stockcode,0),12),"")) -> MINIS ASADO 6'S X12 (APRUB) | P10: =IF(ISBLANK(C10),"",_xlfn.IFNA(INDEX(inbound_data[],MATCH(Outbound_data[[#This Row],[STOCK CODE OUT]],Generated_Stockcode,0),23),"")) -> BXS | Q10: =IF(ISBLANK(C10),"",_xlfn.IFNA(INDEX(inbound_data[],MATCH(Outbound_data[[#This Row],[STOCK CODE OUT]],Generated_Stockcode,0),13),"")) -> LOCAL TRANSFER
B11: 45913 | C11: 126076 | D11: CALOOCAN | E11: DUO-00007A/1064500015 | F11: 70 | G11: 262.08 | H11: 1 | I11: 91909 | J11: IMEE | K11: 74571 | L11: NGN-7085 | N11: =IF(ISBLANK(C11),"",_xlfn.IFNA(INDEX(inbound_data[],MATCH(Outbound_data[[#This Row],[STOCK CODE OUT]],Generated_Stockcode,0),10),"")) -> DUO-00007A/10645 | O11: =IF(ISBLANK(C11),"",_xlfn.IFNA(INDEX(inbound_data[],MATCH(Outbound_data[[#This Row],[STOCK CODE OUT]],Generated_Stockcode,0),12),"")) -> MINIS ASADO 6'S X12 (APRUB) | P11: =IF(ISBLANK(C11),"",_xlfn.IFNA(INDEX(inbound_data[],MATCH(Outbound_data[[#This Row],[STOCK CODE OUT]],Generated_Stockcode,0),23),"")) -> BXS | Q11: =IF(ISBLANK(C11),"",_xlfn.IFNA(INDEX(inbound_data[],MATCH(Outbound_data[[#This Row],[STOCK CODE OUT]],Generated_Stockcode,0),13),"")) -> LOCAL TRANSFER
B12: 45918 | C12: 126677 | D12: MANILA | E12: DUO-00006A/142700014 | F12: 70 | G12: 262.08 | H12: 1 | I12: 92053 | J12: GLADYS | K12: 75186 | L12: CCK-8782 | N12: =IF(ISBLANK(C12),"",_xlfn.IFNA(INDEX(inbound_data[],MATCH(Outbound_data[[#This Row],[STOCK CODE OUT]],Generated_Stockcode,0),10),"")) -> DUO-00006A/1427 | O12: =IF(ISBLANK(C12),"",_xlfn.IFNA(INDEX(inbound_data[],MATCH(Outbound_data[[#This Row],[STOCK CODE OUT]],Generated_Stockcode,0),12),"")) -> MINIS ASADO 6'S X12 (APRUB) | P12: =IF(ISBLANK(C12),"",_xlfn.IFNA(INDEX(inbound_data[],MATCH(Outbound_data[[#This Row],[STOCK CODE OUT]],Generated_Stockcode,0),23),"")) -> BXS | Q12: =IF(ISBLANK(C12),"",_xlfn.IFNA(INDEX(inbound_data[],MATCH(Outbound_data[[#This Row],[STOCK CODE OUT]],Generated_Stockcode,0),13),"")) -> LOCAL TRANSFER
B13: 45918 | C13: 126677 | D13: MANILA | E13: DUO-00008A/449600016 | F13: 70 | G13: 262.08 | H13: 1 | I13: 92053 | J13: GLADYS | K13: 75186 | L13: CCK-8782 | N13: =IF(ISBLANK(C13),"",_xlfn.IFNA(INDEX(inbound_data[],MATCH(Outbound_data[[#This Row],[STOCK CODE OUT]],Generated_Stockcode,0),10),"")) -> DUO-00008A/4496 | O13: =IF(ISBLANK(C13),"",_xlfn.IFNA(INDEX(inbound_data[],MATCH(Outbound_data[[#This Row],[STOCK CODE OUT]],Generated_Stockcode,0),12),"")) -> MINIS ASADO 6'S X12 (APRUB) | P13: =IF(ISBLANK(C13),"",_xlfn.IFNA(INDEX(inbound_data[],MATCH(Outbound_data[[#This Row],[STOCK CODE OUT]],Generated_Stockcode,0),23),"")) -> BXS | Q13: =IF(ISBLANK(C13),"",_xlfn.IFNA(INDEX(inbound_data[],MATCH(Outbound_data[[#This Row],[STOCK CODE OUT]],Generated_Stockcode,0),13),"")) -> LOCAL TRANSFER
B14: 45918 | C14: 126677 | D14: MANILA | E14: DUO-00011A/484400019 | F14: 70 | G14: 262.08 | H14: 1 | I14: 92053 | J14: GLADYS | K14: 75186 | L14: CCK-8782 | N14: =IF(ISBLANK(C14),"",_xlfn.IFNA(INDEX(inbound_data[],MATCH(Outbound_data[[#This Row],[STOCK CODE OUT]],Generated_Stockcode,0),10),"")) -> DUO-00011A/4844 | O14: =IF(ISBLANK(C14),"",_xlfn.IFNA(INDEX(inbound_data[],MATCH(Outbound_data[[#This Row],[STOCK CODE OUT]],Generated_Stockcode,0),12),"")) -> MINIS ASADO 6'S X12 (APRUB) | P14: =IF(ISBLANK(C14),"",_xlfn.IFNA(INDEX(inbound_data[],MATCH(Outbound_data[[#This Row],[STOCK CODE OUT]],Generated_Stockcode,0),23),"")) -> BXS | Q14: =IF(ISBLANK(C14),"",_xlfn.IFNA(INDEX(inbound_data[],MATCH(Outbound_data[[#This Row],[STOCK CODE OUT]],Generated_Stockcode,0),13),"")) -> LOCAL TRANSFER
B15: 45918 | C15: 126677 | D15: MANILA | E15: DUO-00012A/169400020 | F15: 70 | G15: 262.08 | H15: 1 | I15: 92053 | J15: GLADYS | K15: 75186 | L15: CCK-8782 | N15: =IF(ISBLANK(C15),"",_xlfn.IFNA(INDEX(inbound_data[],MATCH(Outbound_data[[#This Row],[STOCK CODE OUT]],Generated_Stockcode,0),10),"")) -> DUO-00012A/1694 | O15: =IF(ISBLANK(C15),"",_xlfn.IFNA(INDEX(inbound_data[],MATCH(Outbound_data[[#This Row],[STOCK CODE OUT]],Generated_Stockcode,0),12),"")) -> MINIS ASADO 6'S X12 (APRUB) | P15: =IF(ISBLANK(C15),"",_xlfn.IFNA(INDEX(inbound_data[],MATCH(Outbound_data[[#This Row],[STOCK CODE OUT]],Generated_Stockcode,0),23),"")) -> BXS | Q15: =IF(ISBLANK(C15),"",_xlfn.IFNA(INDEX(inbound_data[],MATCH(Outbound_data[[#This Row],[STOCK CODE OUT]],Generated_Stockcode,0),13),"")) -> LOCAL TRANSFER
... B109: 46106 | C109: 149652 | D109: 4A4D TRADING CORP | E109: DUO-00102A/383000111 | F109: 70 | G109: 840 | H109: 1 | I109: 114001 | J109: RAF | K109: 98309 | L109: NAU-9473 | N109: =IF(ISBLANK(C109),"",_xlfn.IFNA(INDEX(inbound_data[],MATCH(Outbound_data[[#This Row],[STOCK CODE OUT]],Generated_Stockcode,0),10),"")) -> DUO-00102A/3830 | O109: =IF(ISBLANK(C109),"",_xlfn.IFNA(INDEX(inbound_data[],MATCH(Outbound_data[[#This Row],[STOCK CODE OUT]],Generated_Stockcode,0),12),"")) -> PORK/CHICKEN/BEEF/SHRIMP SIOMAI 30'S 500G (APRUB) | P109: =IF(ISBLANK(C109),"",_xlfn.IFNA(INDEX(inbound_data[],MATCH(Outbound_data[[#This Row],[STOCK CODE OUT]],Generated_Stockcode,0),23),"")) -> BXS | Q109: =IF(ISBLANK(C109),"",_xlfn.IFNA(INDEX(inbound_data[],MATCH(Outbound_data[[#This Row],[STOCK CODE OUT]],Generated_Stockcode,0),13),"")) -> LOCAL TRANSFER
N110: =IF(ISBLANK(C110),"",_xlfn.IFNA(INDEX(inbound_data[],MATCH(Outbound_data[[#This Row],[STOCK CODE OUT]],Generated_Stockcode,0),10),"")) | O110: =IF(ISBLANK(C110),"",_xlfn.IFNA(INDEX(inbound_data[],MATCH(Outbound_data[[#This Row],[STOCK CODE OUT]],Generated_Stockcode,0),12),"")) | P110: =IF(ISBLANK(C110),"",_xlfn.IFNA(INDEX(inbound_data[],MATCH(Outbound_data[[#This Row],[STOCK CODE OUT]],Generated_Stockcode,0),23),"")) | Q110: =IF(ISBLANK(C110),"",_xlfn.IFNA(INDEX(inbound_data[],MATCH(Outbound_data[[#This Row],[STOCK CODE OUT]],Generated_Stockcode,0),13),""))
N111: =IF(ISBLANK(C111),"",_xlfn.IFNA(INDEX(inbound_data[],MATCH(Outbound_data[[#This Row],[STOCK CODE OUT]],Generated_Stockcode,0),10),"")) | O111: =IF(ISBLANK(C111),"",_xlfn.IFNA(INDEX(inbound_data[],MATCH(Outbound_data[[#This Row],[STOCK CODE OUT]],Generated_Stockcode,0),12),"")) | P111: =IF(ISBLANK(C111),"",_xlfn.IFNA(INDEX(inbound_data[],MATCH(Outbound_data[[#This Row],[STOCK CODE OUT]],Generated_Stockcode,0),23),"")) | Q111: =IF(ISBLANK(C111),"",_xlfn.IFNA(INDEX(inbound_data[],MATCH(Outbound_data[[#This Row],[STOCK CODE OUT]],Generated_Stockcode,0),13),""))
N112: =IF(ISBLANK(C112),"",_xlfn.IFNA(INDEX(inbound_data[],MATCH(Outbound_data[[#This Row],[STOCK CODE OUT]],Generated_Stockcode,0),10),"")) | O112: =IF(ISBLANK(C112),"",_xlfn.IFNA(INDEX(inbound_data[],MATCH(Outbound_data[[#This Row],[STOCK CODE OUT]],Generated_Stockcode,0),12),"")) | P112: =IF(ISBLANK(C112),"",_xlfn.IFNA(INDEX(inbound_data[],MATCH(Outbound_data[[#This Row],[STOCK CODE OUT]],Generated_Stockcode,0),23),"")) | Q112: =IF(ISBLANK(C112),"",_xlfn.IFNA(INDEX(inbound_data[],MATCH(Outbound_data[[#This Row],[STOCK CODE OUT]],Generated_Stockcode,0),13),""))
N113: =IF(ISBLANK(C113),"",_xlfn.IFNA(INDEX(inbound_data[],MATCH(Outbound_data[[#This Row],[STOCK CODE OUT]],Generated_Stockcode,0),10),"")) | O113: =IF(ISBLANK(C113),"",_xlfn.IFNA(INDEX(inbound_data[],MATCH(Outbound_data[[#This Row],[STOCK CODE OUT]],Generated_Stockcode,0),12),"")) | P113: =IF(ISBLANK(C113),"",_xlfn.IFNA(INDEX(inbound_data[],MATCH(Outbound_data[[#This Row],[STOCK CODE OUT]],Generated_Stockcode,0),23),"")) | Q113: =IF(ISBLANK(C113),"",_xlfn.IFNA(INDEX(inbound_data[],MATCH(Outbound_data[[#This Row],[STOCK CODE OUT]],Generated_Stockcode,0),13),""))
N114: =IF(ISBLANK(C114),"",_xlfn.IFNA(INDEX(inbound_data[],MATCH(Outbound_data[[#This Row],[STOCK CODE OUT]],Generated_Stockcode,0),10),"")) | O114: =IF(ISBLANK(C114),"",_xlfn.IFNA(INDEX(inbound_data[],MATCH(Outbound_data[[#This Row],[STOCK CODE OUT]],Generated_Stockcode,0),12),"")) | P114: =IF(ISBLANK(C114),"",_xlfn.IFNA(INDEX(inbound_data[],MATCH(Outbound_data[[#This Row],[STOCK CODE OUT]],Generated_Stockcode,0),23),"")) | Q114: =IF(ISBLANK(C114),"",_xlfn.IFNA(INDEX(inbound_data[],MATCH(Outbound_data[[#This Row],[STOCK CODE OUT]],Generated_Stockcode,0),13),""))
N115: =IF(ISBLANK(C115),"",_xlfn.IFNA(INDEX(inbound_data[],MATCH(Outbound_data[[#This Row],[STOCK CODE OUT]],Generated_Stockcode,0),10),"")) | O115: =IF(ISBLANK(C115),"",_xlfn.IFNA(INDEX(inbound_data[],MATCH(Outbound_data[[#This Row],[STOCK CODE OUT]],Generated_Stockcode,0),12),"")) | P115: =IF(ISBLANK(C115),"",_xlfn.IFNA(INDEX(inbound_data[],MATCH(Outbound_data[[#This Row],[STOCK CODE OUT]],Generated_Stockcode,0),23),"")) | Q115: =IF(ISBLANK(C115),"",_xlfn.IFNA(INDEX(inbound_data[],MATCH(Outbound_data[[#This Row],[STOCK CODE OUT]],Generated_Stockcode,0),13),""))
N116: =IF(ISBLANK(C116),"",_xlfn.IFNA(INDEX(inbound_data[],MATCH(Outbound_data[[#This Row],[STOCK CODE OUT]],Generated_Stockcode,0),10),"")) | O116: =IF(ISBLANK(C116),"",_xlfn.IFNA(INDEX(inbound_data[],MATCH(Outbound_data[[#This Row],[STOCK CODE OUT]],Generated_Stockcode,0),12),"")) | P116: =IF(ISBLANK(C116),"",_xlfn.IFNA(INDEX(inbound_data[],MATCH(Outbound_data[[#This Row],[STOCK CODE OUT]],Generated_Stockcode,0),23),"")) | Q116: =IF(ISBLANK(C116),"",_xlfn.IFNA(INDEX(inbound_data[],MATCH(Outbound_data[[#This Row],[STOCK CODE OUT]],Generated_Stockcode,0),13),""))
N117: =IF(ISBLANK(C117),"",_xlfn.IFNA(INDEX(inbound_data[],MATCH(Outbound_data[[#This Row],[STOCK CODE OUT]],Generated_Stockcode,0),10),"")) | O117: =IF(ISBLANK(C117),"",_xlfn.IFNA(INDEX(inbound_data[],MATCH(Outbound_data[[#This Row],[STOCK CODE OUT]],Generated_Stockcode,0),12),"")) | P117: =IF(ISBLANK(C117),"",_xlfn.IFNA(INDEX(inbound_data[],MATCH(Outbound_data[[#This Row],[STOCK CODE OUT]],Generated_Stockcode,0),23),"")) | Q117: =IF(ISBLANK(C117),"",_xlfn.IFNA(INDEX(inbound_data[],MATCH(Outbound_data[[#This Row],[STOCK CODE OUT]],Generated_Stockcode,0),13),""))
N118: =IF(ISBLANK(C118),"",_xlfn.IFNA(INDEX(inbound_data[],MATCH(Outbound_data[[#This Row],[STOCK CODE OUT]],Generated_Stockcode,0),10),"")) | O118: =IF(ISBLANK(C118),"",_xlfn.IFNA(INDEX(inbound_data[],MATCH(Outbound_data[[#This Row],[STOCK CODE OUT]],Generated_Stockcode,0),12),"")) | P118: =IF(ISBLANK(C118),"",_xlfn.IFNA(INDEX(inbound_data[],MATCH(Outbound_data[[#This Row],[STOCK CODE OUT]],Generated_Stockcode,0),23),"")) | Q118: =IF(ISBLANK(C118),"",_xlfn.IFNA(INDEX(inbound_data[],MATCH(Outbound_data[[#This Row],[STOCK CODE OUT]],Generated_Stockcode,0),13),""))
N119: =IF(ISBLANK(C119),"",_xlfn.IFNA(INDEX(inbound_data[],MATCH(Outbound_data[[#This Row],[STOCK CODE OUT]],Generated_Stockcode,0),10),"")) | O119: =IF(ISBLANK(C119),"",_xlfn.IFNA(INDEX(inbound_data[],MATCH(Outbound_data[[#This Row],[STOCK CODE OUT]],Generated_Stockcode,0),12),"")) | P119: =IF(ISBLANK(C119),"",_xlfn.IFNA(INDEX(inbound_data[],MATCH(Outbound_data[[#This Row],[STOCK CODE OUT]],Generated_Stockcode,0),23),"")) | Q119: =IF(ISBLANK(C119),"",_xlfn.IFNA(INDEX(inbound_data[],MATCH(Outbound_data[[#This Row],[STOCK CODE OUT]],Generated_Stockcode,0),13),""))
N120: =IF(ISBLANK(C120),"",_xlfn.IFNA(INDEX(inbound_data[],MATCH(Outbound_data[[#This Row],[STOCK CODE OUT]],Generated_Stockcode,0),10),"")) | O120: =IF(ISBLANK(C120),"",_xlfn.IFNA(INDEX(inbound_data[],MATCH(Outbound_data[[#This Row],[STOCK CODE OUT]],Generated_Stockcode,0),12),"")) | P120: =IF(ISBLANK(C120),"",_xlfn.IFNA(INDEX(inbound_data[],MATCH(Outbound_data[[#This Row],[STOCK CODE OUT]],Generated_Stockcode,0),23),"")) | Q120: =IF(ISBLANK(C120),"",_xlfn.IFNA(INDEX(inbound_data[],MATCH(Outbound_data[[#This Row],[STOCK CODE OUT]],Generated_Stockcode,0),13),""))
N121: =IF(ISBLANK(C121),"",_xlfn.IFNA(INDEX(inbound_data[],MATCH(Outbound_data[[#This Row],[STOCK CODE OUT]],Generated_Stockcode,0),10),"")) | O121: =IF(ISBLANK(C121),"",_xlfn.IFNA(INDEX(inbound_data[],MATCH(Outbound_data[[#This Row],[STOCK CODE OUT]],Generated_Stockcode,0),12),"")) | P121: =IF(ISBLANK(C121),"",_xlfn.IFNA(INDEX(inbound_data[],MATCH(Outbound_data[[#This Row],[STOCK CODE OUT]],Generated_Stockcode,0),23),"")) | Q121: =IF(ISBLANK(C121),"",_xlfn.IFNA(INDEX(inbound_data[],MATCH(Outbound_data[[#This Row],[STOCK CODE OUT]],Generated_Stockcode,0),13),""))
... N1480: =IF(ISBLANK(C1480),"",_xlfn.IFNA(INDEX(inbound_data[],MATCH(Outbound_data[[#This Row],[STOCK CODE OUT]],Generated_Stockcode,0),10),"")) | O1480: =IF(ISBLANK(C1480),"",_xlfn.IFNA(INDEX(inbound_data[],MATCH(Outbound_data[[#This Row],[STOCK CODE OUT]],Generated_Stockcode,0),12),"")) | P1480: =IF(ISBLANK(C1480),"",_xlfn.IFNA(INDEX(inbound_data[],MATCH(Outbound_data[[#This Row],[STOCK CODE OUT]],Generated_Stockcode,0),23),"")) | Q1480: =IF(ISBLANK(C1480),"",_xlfn.IFNA(INDEX(inbound_data[],MATCH(Outbound_data[[#This Row],[STOCK CODE OUT]],Generated_Stockcode,0),13),""))

Sheet Inbound data
D1: VIFEL ICE PLANT AND COLD STORAGE, INC.
D2: Rosas Norte, Saluysoy, Meycauayan. Bulacan
D3: Duopower Foods Inc.
E4: =NOW() -> 46111.157
E5: TOTAL QUANTITY: | F5: =$R$7-'Outbound data'!$F$2 -> 820 | G5: =$T$7-$F$5 -> 0
E6: TOTAL KILOS: | F6: =$S$7-'Outbound data'!$G$2 -> 1853.152 | G6: =$U$7-$F$6 -> -1.8189894e-12
E7: TOTAL PALLETS: | F7: =$K$7-'Outbound data'!$H$2 -> 31 | G7: =$V$7-F7 -> 0 | I7: Total Pallet In: | J7: {=SUM(IF(FREQUENCY(IF(Pallet_Series<>"", MATCH(Pallet_Series,Pallet_Series,0)),ROW(Pallet_Series)-ROW(J9)+1),1))} -> 137 | K7: =SUM(Pallet_qty) -> 137 | L7: =J7-K7 -> 0 | R7: =SUM(In_Quantity) -> 5402 | S7: =SUM(In_Weight) -> 37134.336 | T7: =SUM(Ending_Quantity) -> 820 | U7: =SUM(Ending_Weight) -> 1853.152 | V7: =SUM(Ending_Pallet_Quantity) -> 31 | AA7: L O C A T I O N
A8: Inventory Status | B8: No. | C8: Generated Stockcode | D8: Date Inbound | E8: Mode of Inbound | F8: Receiving Report ref.# | G8: Source | H8: Truck No. | I8: Gatepass | J8: Pallet_Series | K8: Pallet_qty | L8: Item Description | M8: Container Van No. | N8: Production Date | O8: Expiration Date | P8: Ageing Day/s | Q8: Ageing Remarks | R8: In Quantity | S8: In Weight | T8: Ending Quantity | U8: Ending Weight | V8: Ending Pallet Quantity | W8: UOM | X8: WH | Y8: Encoder | Z8: Stock Remarks | AA8: FRZ | AB8: CLM | AC8: RW | AD8: LVL | AE8: SIDE | AF8: From Location | AG8: Location
A9: =IF(ISBLANK(inbound_data[[#This Row],[Receiving Report ref.'#]]),"",IF(inbound_data[[#This Row],[Ending Quantity]]=0,"ZERO","INV")) -> ZERO | B9: =IF(ISBLANK(D9),"",TEXT(ROW(),"00000")) -> 00009 | C9: =IF(ISBLANK(D9),"",inbound_data[[#This Row],[Pallet_Series]]&inbound_data[[#This Row],[No.]]) -> DUO-00001A/633200009 | D9: 45910 | E9: RECEIVING | F9: 101784 | G9: TAGUIG | H9: CCK-8782 | I9: 73296 | J9: DUO-00001A/6332 | K9: 1 | L9: MINIS ASADO 6'S X12 (APRUB) | M9: LOCAL TRANSFER | N9: 45908 | O9: 46454 | P9: =IF(A9="ZERO","",IF(O9="","",O9-TODAY())) | Q9: =IF(A9="ZERO","",IF(P9<0,"ALREADY EXPIRED",IF(P9<60,"NEARLY EXPIRED",""))) | R9: 70 | S9: =+inbound_data[[#This Row],[In Quantity]]*3.744 -> 262.08 | T9: =IF(ISBLANK(R9),0,R9-SUMIF(STOCK_CODE_OUT,$C9,QTY_OUT)) -> 0 | U9: =IF(ISBLANK(S9),0,S9-SUMIF(STOCK_CODE_OUT,$C9,KILOS_OUT)) -> 0 | V9: =IF(ISBLANK(K9),0,K9-SUMIF(STOCK_CODE_OUT,$C9,PALLET_OUT)) -> 0 | W9: BXS | X9: ANNEX | Y9: IMEE | Z9: R | AA9: 4 | AB9: C | AC9: 2 | AD9: 4 | AE9: 1 | AG9: =IF(T9>0,CONCATENATE(AA9,AB9,TEXT(AC9,"R00"),TEXT(AD9,"L0."),TEXT(AE9,"0")),"")
A10: =IF(ISBLANK(inbound_data[[#This Row],[Receiving Report ref.'#]]),"",IF(inbound_data[[#This Row],[Ending Quantity]]=0,"ZERO","INV")) -> ZERO | B10: =IF(ISBLANK(D10),"",TEXT(ROW(),"00000")) -> 00010 | C10: =IF(ISBLANK(D10),"",inbound_data[[#This Row],[Pallet_Series]]&inbound_data[[#This Row],[No.]]) -> DUO-00002A/154300010 | D10: 45910 | E10: RECEIVING | F10: 101784 | G10: TAGUIG | H10: CCK-8782 | I10: 73296 | J10: DUO-00002A/1543 | K10: 1 | L10: MINIS ASADO 6'S X12 (APRUB) | M10: LOCAL TRANSFER | N10: 45908 | O10: 46454 | P10: =IF(A10="ZERO","",IF(O10="","",O10-TODAY())) | Q10: =IF(A10="ZERO","",IF(P10<0,"ALREADY EXPIRED",IF(P10<60,"NEARLY EXPIRED",""))) | R10: 70 | S10: =+inbound_data[[#This Row],[In Quantity]]*3.744 -> 262.08 | T10: =IF(ISBLANK(R10),0,R10-SUMIF(STOCK_CODE_OUT,$C10,QTY_OUT)) -> 0 | U10: =IF(ISBLANK(S10),0,S10-SUMIF(STOCK_CODE_OUT,$C10,KILOS_OUT)) -> 0 | V10: =IF(ISBLANK(K10),0,K10-SUMIF(STOCK_CODE_OUT,$C10,PALLET_OUT)) -> 0 | W10: BXS | X10: ANNEX | Y10: IMEE | Z10: B | AA10: 4 | AB10: C | AC10: 2 | AD10: 5 | AE10: 1 | AG10: =IF(T10>0,CONCATENATE(AA10,AB10,TEXT(AC10,"R00"),TEXT(AD10,"L0."),TEXT(AE10,"0")),"")
A11: =IF(ISBLANK(inbound_data[[#This Row],[Receiving Report ref.'#]]),"",IF(inbound_data[[#This Row],[Ending Quantity]]=0,"ZERO","INV")) -> ZERO | B11: =IF(ISBLANK(D11),"",TEXT(ROW(),"00000")) -> 00011 | C11: =IF(ISBLANK(D11),"",inbound_data[[#This Row],[Pallet_Series]]&inbound_data[[#This Row],[No.]]) -> DUO-00003A/500700011 | D11: 45910 | E11: RECEIVING | F11: 101784 | G11: TAGUIG | H11: CCK-8782 | I11: 73296 | J11: DUO-00003A/5007 | K11: 1 | L11: MINIS ASADO 6'S X12 (APRUB) | M11: LOCAL TRANSFER | N11: 45908 | O11: 46454 | P11: =IF(A11="ZERO","",IF(O11="","",O11-TODAY())) | Q11: =IF(A11="ZERO","",IF(P11<0,"ALREADY EXPIRED",IF(P11<60,"NEARLY EXPIRED",""))) | R11: 70 | S11: =+inbound_data[[#This Row],[In Quantity]]*3.744 -> 262.08 | T11: =IF(ISBLANK(R11),0,R11-SUMIF(STOCK_CODE_OUT,$C11,QTY_OUT)) -> 0 | U11: =IF(ISBLANK(S11),0,S11-SUMIF(STOCK_CODE_OUT,$C11,KILOS_OUT)) -> 0 | V11: =IF(ISBLANK(K11),0,K11-SUMIF(STOCK_CODE_OUT,$C11,PALLET_OUT)) -> 0 | W11: BXS | X11: ANNEX | Y11: IMEE | Z11: R | AA11: 4 | AB11: A | AC11: 9 | AD11: 3 | AE11: 2 | AG11: =IF(T11>0,CONCATENATE(AA11,AB11,TEXT(AC11,"R00"),TEXT(AD11,"L0."),TEXT(AE11,"0")),"")
A12: =IF(ISBLANK(inbound_data[[#This Row],[Receiving Report ref.'#]]),"",IF(inbound_data[[#This Row],[Ending Quantity]]=0,"ZERO","INV")) -> ZERO | B12: =IF(ISBLANK(D12),"",TEXT(ROW(),"00000")) -> 00012 | C12: =IF(ISBLANK(D12),"",inbound_data[[#This Row],[Pallet_Series]]&inbound_data[[#This Row],[No.]]) -> DUO-00004A/NP00012 | D12: 45910 | E12: RECEIVING | F12: 101784 | G12: TAGUIG | H12: CCK-8782 | I12: 73296 | J12: DUO-00004A/NP | K12: 1 | L12: MINIS ASADO 6'S X12 (APRUB) | M12: LOCAL TRANSFER | N12: 45908 | O12: 46454 | P12: =IF(A12="ZERO","",IF(O12="","",O12-TODAY())) | Q12: =IF(A12="ZERO","",IF(P12<0,"ALREADY EXPIRED",IF(P12<60,"NEARLY EXPIRED",""))) | R12: 70 | S12: =+inbound_data[[#This Row],[In Quantity]]*3.744 -> 262.08 | T12: =IF(ISBLANK(R12),0,R12-SUMIF(STOCK_CODE_OUT,$C12,QTY_OUT)) -> 0 | U12: =IF(ISBLANK(S12),0,S12-SUMIF(STOCK_CODE_OUT,$C12,KILOS_OUT)) -> 0 | V12: =IF(ISBLANK(K12),0,K12-SUMIF(STOCK_CODE_OUT,$C12,PALLET_OUT)) -> 0 | W12: BXS | X12: ANNEX | Y12: IMEE | Z12: R | AA12: 4 | AB12: A | AC12: 12 | AD12: 5 | AE12: 1 | AF12: 4AR09L4.1 | AG12: =IF(T12>0,CONCATENATE(AA12,AB12,TEXT(AC12,"R00"),TEXT(AD12,"L0."),TEXT(AE12,"0")),"")
A13: =IF(ISBLANK(inbound_data[[#This Row],[Receiving Report ref.'#]]),"",IF(inbound_data[[#This Row],[Ending Quantity]]=0,"ZERO","INV")) -> ZERO | B13: =IF(ISBLANK(D13),"",TEXT(ROW(),"00000")) -> 00013 | C13: =IF(ISBLANK(D13),"",inbound_data[[#This Row],[Pallet_Series]]&inbound_data[[#This Row],[No.]]) -> DUO-00005A/4182800013 | D13: 45910 | E13: RECEIVING | F13: 101784 | G13: TAGUIG | H13: CCK-8782 | I13: 73296 | J13: DUO-00005A/41828 | K13: 1 | L13: MINIS ASADO 6'S X12 (APRUB) | M13: LOCAL TRANSFER | N13: 45908 | O13: 46454 | P13: =IF(A13="ZERO","",IF(O13="","",O13-TODAY())) | Q13: =IF(A13="ZERO","",IF(P13<0,"ALREADY EXPIRED",IF(P13<60,"NEARLY EXPIRED",""))) | R13: 70 | S13: =+inbound_data[[#This Row],[In Quantity]]*3.744 -> 262.08 | T13: =IF(ISBLANK(R13),0,R13-SUMIF(STOCK_CODE_OUT,$C13,QTY_OUT)) -> 0 | U13: =IF(ISBLANK(S13),0,S13-SUMIF(STOCK_CODE_OUT,$C13,KILOS_OUT)) -> 0 | V13: =IF(ISBLANK(K13),0,K13-SUMIF(STOCK_CODE_OUT,$C13,PALLET_OUT)) -> 0 | W13: BXS | X13: ANNEX | Y13: IMEE | Z13: R | AA13: 4 | AB13: A | AC13: 11 | AD13: 6 | AE13: 2 | AF13: 4AR09L3.1 | AG13: =IF(T13>0,CONCATENATE(AA13,AB13,TEXT(AC13,"R00"),TEXT(AD13,"L0."),TEXT(AE13,"0")),"")
A14: =IF(ISBLANK(inbound_data[[#This Row],[Receiving Report ref.'#]]),"",IF(inbound_data[[#This Row],[Ending Quantity]]=0,"ZERO","INV")) -> ZERO | B14: =IF(ISBLANK(D14),"",TEXT(ROW(),"00000")) -> 00014 | C14: =IF(ISBLANK(D14),"",inbound_data[[#This Row],[Pallet_Series]]&inbound_data[[#This Row],[No.]]) -> DUO-00006A/142700014 | D14: 45910 | E14: RECEIVING | F14: 101784 | G14: TAGUIG | H14: CCK-8782 | I14: 73296 | J14: DUO-00006A/1427 | K14: 1 | L14: MINIS ASADO 6'S X12 (APRUB) | M14: LOCAL TRANSFER | N14: 45908 | O14: 46454 | P14: =IF(A14="ZERO","",IF(O14="","",O14-TODAY())) | Q14: =IF(A14="ZERO","",IF(P14<0,"ALREADY EXPIRED",IF(P14<60,"NEARLY EXPIRED",""))) | R14: 70 | S14: =+inbound_data[[#This Row],[In Quantity]]*3.744 -> 262.08 | T14: =IF(ISBLANK(R14),0,R14-SUMIF(STOCK_CODE_OUT,$C14,QTY_OUT)) -> 0 | U14: =IF(ISBLANK(S14),0,S14-SUMIF(STOCK_CODE_OUT,$C14,KILOS_OUT)) -> 0 | V14: =IF(ISBLANK(K14),0,K14-SUMIF(STOCK_CODE_OUT,$C14,PALLET_OUT)) -> 0 | W14: BXS | X14: ANNEX | Y14: IMEE | Z14: B | AG14: =IF(T14>0,CONCATENATE(AA14,AB14,TEXT(AC14,"R00"),TEXT(AD14,"L0."),TEXT(AE14,"0")),"")
A15: =IF(ISBLANK(inbound_data[[#This Row],[Receiving Report ref.'#]]),"",IF(inbound_data[[#This Row],[Ending Quantity]]=0,"ZERO","INV")) -> ZERO | B15: =IF(ISBLANK(D15),"",TEXT(ROW(),"00000")) -> 00015 | C15: =IF(ISBLANK(D15),"",inbound_data[[#This Row],[Pallet_Series]]&inbound_data[[#This Row],[No.]]) -> DUO-00007A/1064500015 | D15: 45910 | E15: RECEIVING | F15: 101784 | G15: TAGUIG | H15: CCK-8782 | I15: 73296 | J15: DUO-00007A/10645 | K15: 1 | L15: MINIS ASADO 6'S X12 (APRUB) | M15: LOCAL TRANSFER | N15: 45908 | O15: 46454 | P15: =IF(A15="ZERO","",IF(O15="","",O15-TODAY())) | Q15: =IF(A15="ZERO","",IF(P15<0,"ALREADY EXPIRED",IF(P15<60,"NEARLY EXPIRED",""))) | R15: 70 | S15: =+inbound_data[[#This Row],[In Quantity]]*3.744 -> 262.08 | T15: =IF(ISBLANK(R15),0,R15-SUMIF(STOCK_CODE_OUT,$C15,QTY_OUT)) -> 0 | U15: =IF(ISBLANK(S15),0,S15-SUMIF(STOCK_CODE_OUT,$C15,KILOS_OUT)) -> 0 | V15: =IF(ISBLANK(K15),0,K15-SUMIF(STOCK_CODE_OUT,$C15,PALLET_OUT)) -> 0 | W15: BXS | X15: ANNEX | Y15: IMEE | Z15: R | AA15: 4 | AB15: C | AC15: 1 | AD15: 4 | AE15: 2 | AG15: =IF(T15>0,CONCATENATE(AA15,AB15,TEXT(AC15,"R00"),TEXT(AD15,"L0."),TEXT(AE15,"0")),"")
A16: =IF(ISBLANK(inbound_data[[#This Row],[Receiving Report ref.'#]]),"",IF(inbound_data[[#This Row],[Ending Quantity]]=0,"ZERO","INV")) -> ZERO | B16: =IF(ISBLANK(D16),"",TEXT(ROW(),"00000")) -> 00016 | C16: =IF(ISBLANK(D16),"",inbound_data[[#This Row],[Pallet_Series]]&inbound_data[[#This Row],[No.]]) -> DUO-00008A/449600016 | D16: 45910 | E16: RECEIVING | F16: 101784 | G16: TAGUIG | H16: CCK-8782 | I16: 73296 | J16: DUO-00008A/4496 | K16: 1 | L16: MINIS ASADO 6'S X12 (APRUB) | M16: LOCAL TRANSFER | N16: 45908 | O16: 46454 | P16: =IF(A16="ZERO","",IF(O16="","",O16-TODAY())) | Q16: =IF(A16="ZERO","",IF(P16<0,"ALREADY EXPIRED",IF(P16<60,"NEARLY EXPIRED",""))) | R16: 70 | S16: =+inbound_data[[#This Row],[In Quantity]]*3.744 -> 262.08 | T16: =IF(ISBLANK(R16),0,R16-SUMIF(STOCK_CODE_OUT,$C16,QTY_OUT)) -> 0 | U16: =IF(ISBLANK(S16),0,S16-SUMIF(STOCK_CODE_OUT,$C16,KILOS_OUT)) -> 0 | V16: =IF(ISBLANK(K16),0,K16-SUMIF(STOCK_CODE_OUT,$C16,PALLET_OUT)) -> 0 | W16: BXS | X16: ANNEX | Y16: IMEE | Z16: B | AA16: 4 | AB16: C | AC16: 2 | AD16: 4 | AE16: 2 | AG16: =IF(T16>0,CONCATENATE(AA16,AB16,TEXT(AC16,"R00"),TEXT(AD16,"L0."),TEXT(AE16,"0")),"")
A17: =IF(ISBLANK(inbound_data[[#This Row],[Receiving Report ref.'#]]),"",IF(inbound_data[[#This Row],[Ending Quantity]]=0,"ZERO","INV")) -> ZERO | B17: =IF(ISBLANK(D17),"",TEXT(ROW(),"00000")) -> 00017 | C17: =IF(ISBLANK(D17),"",inbound_data[[#This Row],[Pallet_Series]]&inbound_data[[#This Row],[No.]]) -> DUO-00009A/4034100017 | D17: 45910 | E17: RECEIVING | F17: 101784 | G17: TAGUIG | H17: CCK-8782 | I17: 73296 | J17: DUO-00009A/40341 | K17: 1 | L17: MINIS ASADO 6'S X12 (APRUB) | M17: LOCAL TRANSFER | N17: 45908 | O17: 46454 | P17: =IF(A17="ZERO","",IF(O17="","",O17-TODAY())) | Q17: =IF(A17="ZERO","",IF(P17<0,"ALREADY EXPIRED",IF(P17<60,"NEARLY EXPIRED",""))) | R17: 70 | S17: =+inbound_data[[#This Row],[In Quantity]]*3.744 -> 262.08 | T17: =IF(ISBLANK(R17),0,R17-SUMIF(STOCK_CODE_OUT,$C17,QTY_OUT)) -> 0 | U17: =IF(ISBLANK(S17),0,S17-SUMIF(STOCK_CODE_OUT,$C17,KILOS_OUT)) -> 0 | V17: =IF(ISBLANK(K17),0,K17-SUMIF(STOCK_CODE_OUT,$C17,PALLET_OUT)) -> 0 | W17: BXS | X17: ANNEX | Y17: IMEE | Z17: B | AA17: 4 | AB17: C | AC17: 1 | AD17: 3 | AE17: 2 | AG17: =IF(T17>0,CONCATENATE(AA17,AB17,TEXT(AC17,"R00"),TEXT(AD17,"L0."),TEXT(AE17,"0")),"")
A18: =IF(ISBLANK(inbound_data[[#This Row],[Receiving Report ref.'#]]),"",IF(inbound_data[[#This Row],[Ending Quantity]]=0,"ZERO","INV")) -> ZERO | B18: =IF(ISBLANK(D18),"",TEXT(ROW(),"00000")) -> 00018 | C18: =IF(ISBLANK(D18),"",inbound_data[[#This Row],[Pallet_Series]]&inbound_data[[#This Row],[No.]]) -> DUO-00010A/4092100018 | D18: 45910 | E18: RECEIVING | F18: 101784 | G18: TAGUIG | H18: CCK-8782 | I18: 73296 | J18: DUO-00010A/40921 | K18: 1 | L18: MINIS ASADO 6'S X12 (APRUB) | M18: LOCAL TRANSFER | N18: 45908 | O18: 46454 | P18: =IF(A18="ZERO","",IF(O18="","",O18-TODAY())) | Q18: =IF(A18="ZERO","",IF(P18<0,"ALREADY EXPIRED",IF(P18<60,"NEARLY EXPIRED",""))) | R18: 41 | S18: =+inbound_data[[#This Row],[In Quantity]]*3.744 -> 153.504 | T18: =IF(ISBLANK(R18),0,R18-SUMIF(STOCK_CODE_OUT,$C18,QTY_OUT)) -> 0 | U18: =IF(ISBLANK(S18),0,S18-SUMIF(STOCK_CODE_OUT,$C18,KILOS_OUT)) -> 0 | V18: =IF(ISBLANK(K18),0,K18-SUMIF(STOCK_CODE_OUT,$C18,PALLET_OUT)) -> 0 | W18: BXS | X18: ANNEX | Y18: IMEE | Z18: R | AA18: 4 | AB18: C | AC18: 2 | AD18: 5 | AE18: 2 | AG18: =IF(T18>0,CONCATENATE(AA18,AB18,TEXT(AC18,"R00"),TEXT(AD18,"L0."),TEXT(AE18,"0")),"")
A19: =IF(ISBLANK(inbound_data[[#This Row],[Receiving Report ref.'#]]),"",IF(inbound_data[[#This Row],[Ending Quantity]]=0,"ZERO","INV")) -> ZERO | B19: =IF(ISBLANK(D19),"",TEXT(ROW(),"00000")) -> 00019 | C19: =IF(ISBLANK(D19),"",inbound_data[[#This Row],[Pallet_Series]]&inbound_data[[#This Row],[No.]]) -> DUO-00011A/484400019 | D19: 45912 | E19: RECEIVING | F19: 101841 | G19: TAGUIG | H19: CCK-8782 | I19: 73339 | J19: DUO-00011A/4844 | K19: 1 | L19: MINIS ASADO 6'S X12 (APRUB) | M19: LOCAL TRANSFER | N19: 45901 | O19: 46447 | P19: =IF(A19="ZERO","",IF(O19="","",O19-TODAY())) | Q19: =IF(A19="ZERO","",IF(P19<0,"ALREADY EXPIRED",IF(P19<60,"NEARLY EXPIRED",""))) | R19: 70 | S19: 262.08 | T19: =IF(ISBLANK(R19),0,R19-SUMIF(STOCK_CODE_OUT,$C19,QTY_OUT)) -> 0 | U19: =IF(ISBLANK(S19),0,S19-SUMIF(STOCK_CODE_OUT,$C19,KILOS_OUT)) -> 0 | V19: =IF(ISBLANK(K19),0,K19-SUMIF(STOCK_CODE_OUT,$C19,PALLET_OUT)) -> 0 | W19: BXS | X19: ANNEX | Y19: IMEE | Z19: B | AA19: 4 | AB19: A | AC19: 12 | AD19: 5 | AE19: 2 | AG19: =IF(T19>0,CONCATENATE(AA19,AB19,TEXT(AC19,"R00"),TEXT(AD19,"L0."),TEXT(AE19,"0")),"")
A20: =IF(ISBLANK(inbound_data[[#This Row],[Receiving Report ref.'#]]),"",IF(inbound_data[[#This Row],[Ending Quantity]]=0,"ZERO","INV")) -> ZERO | B20: =IF(ISBLANK(D20),"",TEXT(ROW(),"00000")) -> 00020 | C20: =IF(ISBLANK(D20),"",inbound_data[[#This Row],[Pallet_Series]]&inbound_data[[#This Row],[No.]]) -> DUO-00012A/169400020 | D20: 45912 | E20: RECEIVING | F20: 101841 | G20: TAGUIG | H20: CCK-8782 | I20: 73339 | J20: DUO-00012A/1694 | K20: 1 | L20: MINIS ASADO 6'S X12 (APRUB) | M20: LOCAL TRANSFER | N20: 45901 | O20: 46447 | P20: =IF(A20="ZERO","",IF(O20="","",O20-TODAY())) | Q20: =IF(A20="ZERO","",IF(P20<0,"ALREADY EXPIRED",IF(P20<60,"NEARLY EXPIRED",""))) | R20: 70 | S20: 262.08 | T20: =IF(ISBLANK(R20),0,R20-SUMIF(STOCK_CODE_OUT,$C20,QTY_OUT)) -> 0 | U20: =IF(ISBLANK(S20),0,S20-SUMIF(STOCK_CODE_OUT,$C20,KILOS_OUT)) -> 0 | V20: =IF(ISBLANK(K20),0,K20-SUMIF(STOCK_CODE_OUT,$C20,PALLET_OUT)) -> 0 | W20: BXS | X20: ANNEX | Y20: IMEE | Z20: B | AA20: 4 | AB20: A | AC20: 12 | AD20: 6 | AE20: 1 | AG20: =IF(T20>0,CONCATENATE(AA20,AB20,TEXT(AC20,"R00"),TEXT(AD20,"L0."),TEXT(AE20,"0")),"")
A21: =IF(ISBLANK(inbound_data[[#This Row],[Receiving Report ref.'#]]),"",IF(inbound_data[[#This Row],[Ending Quantity]]=0,"ZERO","INV")) -> ZERO | B21: =IF(ISBLANK(D21),"",TEXT(ROW(),"00000")) -> 00021 | C21: =IF(ISBLANK(D21),"",inbound_data[[#This Row],[Pallet_Series]]&inbound_data[[#This Row],[No.]]) -> DUO-00013A/380000021 | D21: 45912 | E21: RECEIVING | F21: 101841 | G21: TAGUIG | H21: CCK-8782 | I21: 73339 | J21: DUO-00013A/3800 | K21: 1 | L21: MINIS ASADO 6'S X12 (APRUB) | M21: LOCAL TRANSFER | N21: 45901 | O21: 46447 | P21: =IF(A21="ZERO","",IF(O21="","",O21-TODAY())) | Q21: =IF(A21="ZERO","",IF(P21<0,"ALREADY EXPIRED",IF(P21<60,"NEARLY EXPIRED",""))) | R21: 70 | S21: 262.08 | T21: =IF(ISBLANK(R21),0,R21-SUMIF(STOCK_CODE_OUT,$C21,QTY_OUT)) -> 0 | U21: =IF(ISBLANK(S21),0,S21-SUMIF(STOCK_CODE_OUT,$C21,KILOS_OUT)) -> 0 | V21: =IF(ISBLANK(K21),0,K21-SUMIF(STOCK_CODE_OUT,$C21,PALLET_OUT)) -> 0 | W21: BXS | X21: ANNEX | Y21: IMEE | Z21: R | AA21: 4 | AB21: A | AC21: 11 | AD21: 6 | AE21: 1 | AG21: =IF(T21>0,CONCATENATE(AA21,AB21,TEXT(AC21,"R00"),TEXT(AD21,"L0."),TEXT(AE21,"0")),"")
A22: =IF(ISBLANK(inbound_data[[#This Row],[Receiving Report ref.'#]]),"",IF(inbound_data[[#This Row],[Ending Quantity]]=0,"ZERO","INV")) -> ZERO | B22: =IF(ISBLANK(D22),"",TEXT(ROW(),"00000")) -> 00022 | C22: =IF(ISBLANK(D22),"",inbound_data[[#This Row],[Pallet_Series]]&inbound_data[[#This Row],[No.]]) -> DUO-00014A/854300022 | D22: 45912 | E22: RECEIVING | F22: 101841 | G22: TAGUIG | H22: CCK-8782 | I22: 73339 | J22: DUO-00014A/8543 | K22: 1 | L22: MINIS ASADO 6'S X12 (APRUB) | M22: LOCAL TRANSFER | N22: 45901 | O22: 46447 | P22: =IF(A22="ZERO","",IF(O22="","",O22-TODAY())) | Q22: =IF(A22="ZERO","",IF(P22<0,"ALREADY EXPIRED",IF(P22<60,"NEARLY EXPIRED",""))) | R22: 70 | S22: 262.08 | T22: =IF(ISBLANK(R22),0,R22-SUMIF(STOCK_CODE_OUT,$C22,QTY_OUT)) -> 0 | U22: =IF(ISBLANK(S22),0,S22-SUMIF(STOCK_CODE_OUT,$C22,KILOS_OUT)) -> 0 | V22: =IF(ISBLANK(K22),0,K22-SUMIF(STOCK_CODE_OUT,$C22,PALLET_OUT)) -> 0 | W22: BXS | X22: ANNEX | Y22: IMEE | Z22: R | AA22: 4 | AB22: A | AC22: 12 | AD22: 6 | AE22: 2 | AG22: =IF(T22>0,CONCATENATE(AA22,AB22,TEXT(AC22,"R00"),TEXT(AD22,"L0."),TEXT(AE22,"0")),"")
A23: =IF(ISBLANK(inbound_data[[#This Row],[Receiving Report ref.'#]]),"",IF(inbound_data[[#This Row],[Ending Quantity]]=0,"ZERO","INV")) -> ZERO | B23: =IF(ISBLANK(D23),"",TEXT(ROW(),"00000")) -> 00023 | C23: =IF(ISBLANK(D23),"",inbound_data[[#This Row],[Pallet_Series]]&inbound_data[[#This Row],[No.]]) -> DUO-00015A/1061000023 | D23: 45918 | E23: RECEIVING | F23: 102348 | G23: TAGUIG | H23: CCK-8782 | I23: 75186 | J23: DUO-00015A/10610 | K23: 1 | L23: PORK ASADO SIOPAO 1.3 KG (CHIBAO) | M23: LOCAL TRANSFER | N23: 45916 | O23: 46462 | P23: =IF(A23="ZERO","",IF(O23="","",O23-TODAY())) | Q23: =IF(A23="ZERO","",IF(P23<0,"ALREADY EXPIRED",IF(P23<60,"NEARLY EXPIRED",""))) | R23: 30 | S23: 312 | T23: =IF(ISBLANK(R23),0,R23-SUMIF(STOCK_CODE_OUT,$C23,QTY_OUT)) -> 0 | U23: =IF(ISBLANK(S23),0,S23-SUMIF(STOCK_CODE_OUT,$C23,KILOS_OUT)) -> 0 | V23: =IF(ISBLANK(K23),0,K23-SUMIF(STOCK_CODE_OUT,$C23,PALLET_OUT)) -> 0 | W23: BXS | X23: ANNEX | Y23: GLADYS | Z23: R | AG23: =IF(T23>0,CONCATENATE(AA23,AB23,TEXT(AC23,"R00"),TEXT(AD23,"L0."),TEXT(AE23,"0")),"")
A24: =IF(ISBLANK(inbound_data[[#This Row],[Receiving Report ref.'#]]),"",IF(inbound_data[[#This Row],[Ending Quantity]]=0,"ZERO","INV")) -> ZERO | B24: =IF(ISBLANK(D24),"",TEXT(ROW(),"00000")) -> 00024 | C24: =IF(ISBLANK(D24),"",inbound_data[[#This Row],[Pallet_Series]]&inbound_data[[#This Row],[No.]]) -> DUO-00016A/399900024 | D24: 45918 | E24: RECEIVING | F24: 102348 | G24: TAGUIG | H24: CCK-8782 | I24: 75186 | J24: DUO-00016A/3999 | K24: 1 | L24: PORK ASADO SIOPAO 1.3 KG (CHIBAO) | M24: LOCAL TRANSFER | N24: 45916 | O24: 46462 | P24: =IF(A24="ZERO","",IF(O24="","",O24-TODAY())) | Q24: =IF(A24="ZERO","",IF(P24<0,"ALREADY EXPIRED",IF(P24<60,"NEARLY EXPIRED",""))) | R24: 30 | S24: 312 | T24: =IF(ISBLANK(R24),0,R24-SUMIF(STOCK_CODE_OUT,$C24,QTY_OUT)) -> 0 | U24: =IF(ISBLANK(S24),0,S24-SUMIF(STOCK_CODE_OUT,$C24,KILOS_OUT)) -> 0 | V24: =IF(ISBLANK(K24),0,K24-SUMIF(STOCK_CODE_OUT,$C24,PALLET_OUT)) -> 0 | W24: BXS | X24: ANNEX | Y24: GLADYS | Z24: R | AG24: =IF(T24>0,CONCATENATE(AA24,AB24,TEXT(AC24,"R00"),TEXT(AD24,"L0."),TEXT(AE24,"0")),"")
A25: =IF(ISBLANK(inbound_data[[#This Row],[Receiving Report ref.'#]]),"",IF(inbound_data[[#This Row],[Ending Quantity]]=0,"ZERO","INV")) -> ZERO | B25: =IF(ISBLANK(D25),"",TEXT(ROW(),"00000")) -> 00025 | C25: =IF(ISBLANK(D25),"",inbound_data[[#This Row],[Pallet_Series]]&inbound_data[[#This Row],[No.]]) -> DUO-00017A/884700025 | D25: 45918 | E25: RECEIVING | F25: 102348 | G25: TAGUIG | H25: CCK-8782 | I25: 75186 | J25: DUO-00017A/8847 | K25: 1 | L25: PORK ASADO SIOPAO 1.3 KG (CHIBAO) | M25: LOCAL TRANSFER | N25: 45916 | O25: 46462 | P25: =IF(A25="ZERO","",IF(O25="","",O25-TODAY())) | Q25: =IF(A25="ZERO","",IF(P25<0,"ALREADY EXPIRED",IF(P25<60,"NEARLY EXPIRED",""))) | R25: 30 | S25: 312 | T25: =IF(ISBLANK(R25),0,R25-SUMIF(STOCK_CODE_OUT,$C25,QTY_OUT)) -> 0 | U25: =IF(ISBLANK(S25),0,S25-SUMIF(STOCK_CODE_OUT,$C25,KILOS_OUT)) -> 0 | V25: =IF(ISBLANK(K25),0,K25-SUMIF(STOCK_CODE_OUT,$C25,PALLET_OUT)) -> 0 | W25: BXS | X25: ANNEX | Y25: GLADYS | Z25: R | AG25: =IF(T25>0,CONCATENATE(AA25,AB25,TEXT(AC25,"R00"),TEXT(AD25,"L0."),TEXT(AE25,"0")),"")
A26: =IF(ISBLANK(inbound_data[[#This Row],[Receiving Report ref.'#]]),"",IF(inbound_data[[#This Row],[Ending Quantity]]=0,"ZERO","INV")) -> ZERO | B26: =IF(ISBLANK(D26),"",TEXT(ROW(),"00000")) -> 00026 | C26: =IF(ISBLANK(D26),"",inbound_data[[#This Row],[Pallet_Series]]&inbound_data[[#This Row],[No.]]) -> DUO-00018A/476400026 | D26: 45918 | E26: RECEIVING | F26: 102348 | G26: TAGUIG | H26: CCK-8782 | I26: 75186 | J26: DUO-00018A/4764 | K26: 1 | L26: PORK ASADO SIOPAO 1.3 KG (CHIBAO) | M26: LOCAL TRANSFER | N26: 45916 | O26: 46462 | P26: =IF(A26="ZERO","",IF(O26="","",O26-TODAY())) | Q26: =IF(A26="ZERO","",IF(P26<0,"ALREADY EXPIRED",IF(P26<60,"NEARLY EXPIRED",""))) | R26: 30 | S26: 312 | T26: =IF(ISBLANK(R26),0,R26-SUMIF(STOCK_CODE_OUT,$C26,QTY_OUT)) -> 0 | U26: =IF(ISBLANK(S26),0,S26-SUMIF(STOCK_CODE_OUT,$C26,KILOS_OUT)) -> 0 | V26: =IF(ISBLANK(K26),0,K26-SUMIF(STOCK_CODE_OUT,$C26,PALLET_OUT)) -> 0 | W26: BXS | X26: ANNEX | Y26: GLADYS | Z26: B | AG26: =IF(T26>0,CONCATENATE(AA26,AB26,TEXT(AC26,"R00"),TEXT(AD26,"L0."),TEXT(AE26,"0")),"")
A27: =IF(ISBLANK(inbound_data[[#This Row],[Receiving Report ref.'#]]),"",IF(inbound_data[[#This Row],[Ending Quantity]]=0,"ZERO","INV")) -> ZERO | B27: =IF(ISBLANK(D27),"",TEXT(ROW(),"00000")) -> 00027 | C27: =IF(ISBLANK(D27),"",inbound_data[[#This Row],[Pallet_Series]]&inbound_data[[#This Row],[No.]]) -> DUO-00019A/610500027 | D27: 45918 | E27: RECEIVING | F27: 102348 | G27: TAGUIG | H27: CCK-8782 | I27: 75186 | J27: DUO-00019A/6105 | K27: 1 | L27: PORK ASADO SIOPAO 1.3 KG (CHIBAO) | M27: LOCAL TRANSFER | N27: 45916 | O27: 46462 | P27: =IF(A27="ZERO","",IF(O27="","",O27-TODAY())) | Q27: =IF(A27="ZERO","",IF(P27<0,"ALREADY EXPIRED",IF(P27<60,"NEARLY EXPIRED",""))) | R27: 30 | S27: 312 | T27: =IF(ISBLANK(R27),0,R27-SUMIF(STOCK_CODE_OUT,$C27,QTY_OUT)) -> 0 | U27: =IF(ISBLANK(S27),0,S27-SUMIF(STOCK_CODE_OUT,$C27,KILOS_OUT)) -> 0 | V27: =IF(ISBLANK(K27),0,K27-SUMIF(STOCK_CODE_OUT,$C27,PALLET_OUT)) -> 0 | W27: BXS | X27: ANNEX | Y27: GLADYS | Z27: R | AG27: =IF(T27>0,CONCATENATE(AA27,AB27,TEXT(AC27,"R00"),TEXT(AD27,"L0."),TEXT(AE27,"0")),"")
A28: =IF(ISBLANK(inbound_data[[#This Row],[Receiving Report ref.'#]]),"",IF(inbound_data[[#This Row],[Ending Quantity]]=0,"ZERO","INV")) -> ZERO | B28: =IF(ISBLANK(D28),"",TEXT(ROW(),"00000")) -> 00028 | C28: =IF(ISBLANK(D28),"",inbound_data[[#This Row],[Pallet_Series]]&inbound_data[[#This Row],[No.]]) -> DUO-00020A/4155400028 | D28: 45918 | E28: RECEIVING | F28: 102348 | G28: TAGUIG | H28: CCK-8782 | I28: 75186 | J28: DUO-00020A/41554 | K28: 1 | L28: PORK ASADO SIOPAO 1.3 KG (CHIBAO) | M28: LOCAL TRANSFER | N28: 45916 | O28: 46462 | P28: =IF(A28="ZERO","",IF(O28="","",O28-TODAY())) | Q28: =IF(A28="ZERO","",IF(P28<0,"ALREADY EXPIRED",IF(P28<60,"NEARLY EXPIRED",""))) | R28: 30 | S28: 312 | T28: =IF(ISBLANK(R28),0,R28-SUMIF(STOCK_CODE_OUT,$C28,QTY_OUT)) -> 0 | U28: =IF(ISBLANK(S28),0,S28-SUMIF(STOCK_CODE_OUT,$C28,KILOS_OUT)) -> 0 | V28: =IF(ISBLANK(K28),0,K28-SUMIF(STOCK_CODE_OUT,$C28,PALLET_OUT)) -> 0 | W28: BXS | X28: ANNEX | Y28: GLADYS | Z28: B | AA28: 2 | AB28: A | AC28: 6 | AD28: 3 | AE28: 1 | AG28: =IF(T28>0,CONCATENATE(AA28,AB28,TEXT(AC28,"R00"),TEXT(AD28,"L0."),TEXT(AE28,"0")),"")
A29: =IF(ISBLANK(inbound_data[[#This Row],[Receiving Report ref.'#]]),"",IF(inbound_data[[#This Row],[Ending Quantity]]=0,"ZERO","INV")) -> ZERO | B29: =IF(ISBLANK(D29),"",TEXT(ROW(),"00000")) -> 00029 | C29: =IF(ISBLANK(D29),"",inbound_data[[#This Row],[Pallet_Series]]&inbound_data[[#This Row],[No.]]) -> DUO-00021A/308000029 | D29: 45918 | E29: RECEIVING | F29: 102348 | G29: TAGUIG | H29: CCK-8782 | I29: 75186 | J29: DUO-00021A/3080 | K29: 1 | L29: PORK ASADO SIOPAO 1.3 KG (CHIBAO) | M29: LOCAL TRANSFER | N29: 45916 | O29: 46462 | P29: =IF(A29="ZERO","",IF(O29="","",O29-TODAY())) | Q29: =IF(A29="ZERO","",IF(P29<0,"ALREADY EXPIRED",IF(P29<60,"NEARLY EXPIRED",""))) | R29: 30 | S29: 312 | T29: =IF(ISBLANK(R29),0,R29-SUMIF(STOCK_CODE_OUT,$C29,QTY_OUT)) -> 0 | U29: =IF(ISBLANK(S29),0,S29-SUMIF(STOCK_CODE_OUT,$C29,KILOS_OUT)) -> 0 | V29: =IF(ISBLANK(K29),0,K29-SUMIF(STOCK_CODE_OUT,$C29,PALLET_OUT)) -> 0 | W29: BXS | X29: ANNEX | Y29: GLADYS | Z29: R | AA29: 2 | AB29: A | AC29: 6 | AD29: 4 | AE29: 2 | AG29: =IF(T29>0,CONCATENATE(AA29,AB29,TEXT(AC29,"R00"),TEXT(AD29,"L0."),TEXT(AE29,"0")),"")
A30: =IF(ISBLANK(inbound_data[[#This Row],[Receiving Report ref.'#]]),"",IF(inbound_data[[#This Row],[Ending Quantity]]=0,"ZERO","INV")) -> ZERO | B30: =IF(ISBLANK(D30),"",TEXT(ROW(),"00000")) -> 00030 | C30: =IF(ISBLANK(D30),"",inbound_data[[#This Row],[Pallet_Series]]&inbound_data[[#This Row],[No.]]) -> DUO-00022A/NP00030 | D30: 45944 | E30: RECEIVING | F30: 105131 | G30: CALOOCAN | H30: CCK-8782 | I30: 78680 | J30: DUO-00022A/NP | K30: 1 | L30: ASADO SIOPAO 30'S (500G) (CHIBAO) | M30: LOCAL TRANSFER | N30: 45931 | O30: 46478 | P30: =IF(A30="ZERO","",IF(O30="","",O30-TODAY())) | Q30: =IF(A30="ZERO","",IF(P30<0,"ALREADY EXPIRED",IF(P30<60,"NEARLY EXPIRED",""))) | R30: 50 | S30: =50*12 -> 600 | T30: =IF(ISBLANK(R30),0,R30-SUMIF(STOCK_CODE_OUT,$C30,QTY_OUT)) -> 0 | U30: =IF(ISBLANK(S30),0,S30-SUMIF(STOCK_CODE_OUT,$C30,KILOS_OUT)) -> 0 | V30: =IF(ISBLANK(K30),0,K30-SUMIF(STOCK_CODE_OUT,$C30,PALLET_OUT)) -> 0 | W30: BXS | X30: ANNEX | Y30: LAINE | Z30: R | AG30: =IF(T30>0,CONCATENATE(AA30,AB30,TEXT(AC30,"R00"),TEXT(AD30,"L0."),TEXT(AE30,"0")),"")
A31: =IF(ISBLANK(inbound_data[[#This Row],[Receiving Report ref.'#]]),"",IF(inbound_data[[#This Row],[Ending Quantity]]=0,"ZERO","INV")) -> ZERO | B31: =IF(ISBLANK(D31),"",TEXT(ROW(),"00000")) -> 00031 | C31: =IF(ISBLANK(D31),"",inbound_data[[#This Row],[Pallet_Series]]&inbound_data[[#This Row],[No.]]) -> DUO-00023A/163900031 | D31: 45944 | E31: RECEIVING | F31: 105131 | G31: CALOOCAN | H31: CCK-8782 | I31: 78680 | J31: DUO-00023A/1639 | K31: 1 | L31: ASADO SIOPAO 30'S (500G) (CHIBAO) | M31: LOCAL TRANSFER | N31: 45931 | O31: 46478 | P31: =IF(A31="ZERO","",IF(O31="","",O31-TODAY())) | Q31: =IF(A31="ZERO","",IF(P31<0,"ALREADY EXPIRED",IF(P31<60,"NEARLY EXPIRED",""))) | R31: 37 | S31: =37*12 -> 444 | T31: =IF(ISBLANK(R31),0,R31-SUMIF(STOCK_CODE_OUT,$C31,QTY_OUT)) -> 0 | U31: =IF(ISBLANK(S31),0,S31-SUMIF(STOCK_CODE_OUT,$C31,KILOS_OUT)) -> 0 | V31: =IF(ISBLANK(K31),0,K31-SUMIF(STOCK_CODE_OUT,$C31,PALLET_OUT)) -> 0 | W31: BXS | X31: ANNEX | Y31: LAINE | Z31: B | AG31: =IF(T31>0,CONCATENATE(AA31,AB31,TEXT(AC31,"R00"),TEXT(AD31,"L0."),TEXT(AE31,"0")),"")
A32: =IF(ISBLANK(inbound_data[[#This Row],[Receiving Report ref.'#]]),"",IF(inbound_data[[#This Row],[Ending Quantity]]=0,"ZERO","INV")) -> ZERO | B32: =IF(ISBLANK(D32),"",TEXT(ROW(),"00000")) -> 00032 | C32: =IF(ISBLANK(D32),"",inbound_data[[#This Row],[Pallet_Series]]&inbound_data[[#This Row],[No.]]) -> DUO-00024A/1003300032 | D32: 45944 | E32: RECEIVING | F32: 105131 | G32: CALOOCAN | H32: CCK-8782 | I32: 78680 | J32: DUO-00024A/10033 | K32: 1 | L32: ASADO SIOPAO 10'S (1.3 KG) (CHIBAO) | M32: LOCAL TRANSFER | N32: 45931 | O32: 46478 | P32: =IF(A32="ZERO","",IF(O32="","",O32-TODAY())) | Q32: =IF(A32="ZERO","",IF(P32<0,"ALREADY EXPIRED",IF(P32<60,"NEARLY EXPIRED",""))) | R32: 30 | S32: =30*10.4 -> 312 | T32: =IF(ISBLANK(R32),0,R32-SUMIF(STOCK_CODE_OUT,$C32,QTY_OUT)) -> 0 | U32: =IF(ISBLANK(S32),0,S32-SUMIF(STOCK_CODE_OUT,$C32,KILOS_OUT)) -> 0 | V32: =IF(ISBLANK(K32),0,K32-SUMIF(STOCK_CODE_OUT,$C32,PALLET_OUT)) -> 0 | W32: BXS | X32: ANNEX | Y32: LAINE | Z32: R | AG32: =IF(T32>0,CONCATENATE(AA32,AB32,TEXT(AC32,"R00"),TEXT(AD32,"L0."),TEXT(AE32,"0")),"")
A33: =IF(ISBLANK(inbound_data[[#This Row],[Receiving Report ref.'#]]),"",IF(inbound_data[[#This Row],[Ending Quantity]]=0,"ZERO","INV")) -> ZERO | B33: =IF(ISBLANK(D33),"",TEXT(ROW(),"00000")) -> 00033 | C33: =IF(ISBLANK(D33),"",inbound_data[[#This Row],[Pallet_Series]]&inbound_data[[#This Row],[No.]]) -> DUO-00025A/94600033 | D33: 45944 | E33: RECEIVING | F33: 105131 | G33: CALOOCAN | H33: CCK-8782 | I33: 78680 | J33: DUO-00025A/946 | K33: 1 | L33: ASADO SIOPAO 10'S (1.3 KG) (CHIBAO) | M33: LOCAL TRANSFER | N33: 45931 | O33: 46478 | P33: =IF(A33="ZERO","",IF(O33="","",O33-TODAY())) | Q33: =IF(A33="ZERO","",IF(P33<0,"ALREADY EXPIRED",IF(P33<60,"NEARLY EXPIRED",""))) | R33: 30 | S33: =30*10.4 -> 312 | T33: =IF(ISBLANK(R33),0,R33-SUMIF(STOCK_CODE_OUT,$C33,QTY_OUT)) -> 0 | U33: =IF(ISBLANK(S33),0,S33-SUMIF(STOCK_CODE_OUT,$C33,KILOS_OUT)) -> 0 | V33: =IF(ISBLANK(K33),0,K33-SUMIF(STOCK_CODE_OUT,$C33,PALLET_OUT)) -> 0 | W33: BXS | X33: ANNEX | Y33: LAINE | Z33: R | AG33: =IF(T33>0,CONCATENATE(AA33,AB33,TEXT(AC33,"R00"),TEXT(AD33,"L0."),TEXT(AE33,"0")),"")
A34: =IF(ISBLANK(inbound_data[[#This Row],[Receiving Report ref.'#]]),"",IF(inbound_data[[#This Row],[Ending Quantity]]=0,"ZERO","INV")) -> ZERO | B34: =IF(ISBLANK(D34),"",TEXT(ROW(),"00000")) -> 00034 | C34: =IF(ISBLANK(D34),"",inbound_data[[#This Row],[Pallet_Series]]&inbound_data[[#This Row],[No.]]) -> DUO-00026A/701700034 | D34: 45944 | E34: RECEIVING | F34: 105131 | G34: CALOOCAN | H34: CCK-8782 | I34: 78680 | J34: DUO-00026A/7017 | K34: 1 | L34: ASADO SIOPAO 10'S (1.3 KG) (CHIBAO) | M34: LOCAL TRANSFER | N34: 45931 | O34: 46478 | P34: =IF(A34="ZERO","",IF(O34="","",O34-TODAY())) | Q34: =IF(A34="ZERO","",IF(P34<0,"ALREADY EXPIRED",IF(P34<60,"NEARLY EXPIRED",""))) | R34: 30 | S34: =30*10.4 -> 312 | T34: =IF(ISBLANK(R34),0,R34-SUMIF(STOCK_CODE_OUT,$C34,QTY_OUT)) -> 0 | U34: =IF(ISBLANK(S34),0,S34-SUMIF(STOCK_CODE_OUT,$C34,KILOS_OUT)) -> 0 | V34: =IF(ISBLANK(K34),0,K34-SUMIF(STOCK_CODE_OUT,$C34,PALLET_OUT)) -> 0 | W34: BXS | X34: ANNEX | Y34: LAINE | Z34: R | AG34: =IF(T34>0,CONCATENATE(AA34,AB34,TEXT(AC34,"R00"),TEXT(AD34,"L0."),TEXT(AE34,"0")),"")
A35: =IF(ISBLANK(inbound_data[[#This Row],[Receiving Report ref.'#]]),"",IF(inbound_data[[#This Row],[Ending Quantity]]=0,"ZERO","INV")) -> ZERO | B35: =IF(ISBLANK(D35),"",TEXT(ROW(),"00000")) -> 00035 | C35: =IF(ISBLANK(D35),"",inbound_data[[#This Row],[Pallet_Series]]&inbound_data[[#This Row],[No.]]) -> DUO-00027A/626900035 | D35: 45944 | E35: RECEIVING | F35: 105131 | G35: CALOOCAN | H35: CCK-8782 | I35: 78680 | J35: DUO-00027A/6269 | K35: 1 | L35: ASADO SIOPAO 10'S (1.3 KG) (CHIBAO) | M35: LOCAL TRANSFER | N35: 45931 | O35: 46478 | P35: =IF(A35="ZERO","",IF(O35="","",O35-TODAY())) | Q35: =IF(A35="ZERO","",IF(P35<0,"ALREADY EXPIRED",IF(P35<60,"NEARLY EXPIRED",""))) | R35: 30 | S35: =30*10.4 -> 312 | T35: =IF(ISBLANK(R35),0,R35-SUMIF(STOCK_CODE_OUT,$C35,QTY_OUT)) -> 0 | U35: =IF(ISBLANK(S35),0,S35-SUMIF(STOCK_CODE_OUT,$C35,KILOS_OUT)) -> 0 | V35: =IF(ISBLANK(K35),0,K35-SUMIF(STOCK_CODE_OUT,$C35,PALLET_OUT)) -> 0 | W35: BXS | X35: ANNEX | Y35: LAINE | Z35: R | AG35: =IF(T35>0,CONCATENATE(AA35,AB35,TEXT(AC35,"R00"),TEXT(AD35,"L0."),TEXT(AE35,"0")),"")
A36: =IF(ISBLANK(inbound_data[[#This Row],[Receiving Report ref.'#]]),"",IF(inbound_data[[#This Row],[Ending Quantity]]=0,"ZERO","INV")) -> ZERO | B36: =IF(ISBLANK(D36),"",TEXT(ROW(),"00000")) -> 00036 | C36: =IF(ISBLANK(D36),"",inbound_data[[#This Row],[Pallet_Series]]&inbound_data[[#This Row],[No.]]) -> DUO-00028A/47800036 | D36: 45944 | E36: RECEIVING | F36: 105131 | G36: CALOOCAN | H36: CCK-8782 | I36: 78680 | J36: DUO-00028A/478 | K36: 1 | L36: ASADO SIOPAO 10'S (1.3 KG) (CHIBAO) | M36: LOCAL TRANSFER | N36: 45931 | O36: 46478 | P36: =IF(A36="ZERO","",IF(O36="","",O36-TODAY())) | Q36: =IF(A36="ZERO","",IF(P36<0,"ALREADY EXPIRED",IF(P36<60,"NEARLY EXPIRED",""))) | R36: 30 | S36: =30*10.4 -> 312 | T36: =IF(ISBLANK(R36),0,R36-SUMIF(STOCK_CODE_OUT,$C36,QTY_OUT)) -> 0 | U36: =IF(ISBLANK(S36),0,S36-SUMIF(STOCK_CODE_OUT,$C36,KILOS_OUT)) -> 0 | V36: =IF(ISBLANK(K36),0,K36-SUMIF(STOCK_CODE_OUT,$C36,PALLET_OUT)) -> 0 | W36: BXS | X36: ANNEX | Y36: LAINE | Z36: R | AG36: =IF(T36>0,CONCATENATE(AA36,AB36,TEXT(AC36,"R00"),TEXT(AD36,"L0."),TEXT(AE36,"0")),"")
A37: =IF(ISBLANK(inbound_data[[#This Row],[Receiving Report ref.'#]]),"",IF(inbound_data[[#This Row],[Ending Quantity]]=0,"ZERO","INV")) -> ZERO | B37: =IF(ISBLANK(D37),"",TEXT(ROW(),"00000")) -> 00037 | C37: =IF(ISBLANK(D37),"",inbound_data[[#This Row],[Pallet_Series]]&inbound_data[[#This Row],[No.]]) -> DUO-00029A/162000037 | D37: 45944 | E37: RECEIVING | F37: 105131 | G37: CALOOCAN | H37: CCK-8782 | I37: 78680 | J37: DUO-00029A/1620 | K37: 1 | L37: ASADO SIOPAO 10'S (1.3 KG) (CHIBAO) | M37: LOCAL TRANSFER | N37: 45931 | O37: 46478 | P37: =IF(A37="ZERO","",IF(O37="","",O37-TODAY())) | Q37: =IF(A37="ZERO","",IF(P37<0,"ALREADY EXPIRED",IF(P37<60,"NEARLY EXPIRED",""))) | R37: 30 | S37: =30*10.4 -> 312 | T37: =IF(ISBLANK(R37),0,R37-SUMIF(STOCK_CODE_OUT,$C37,QTY_OUT)) -> 0 | U37: =IF(ISBLANK(S37),0,S37-SUMIF(STOCK_CODE_OUT,$C37,KILOS_OUT)) -> 0 | V37: =IF(ISBLANK(K37),0,K37-SUMIF(STOCK_CODE_OUT,$C37,PALLET_OUT)) -> 0 | W37: BXS | X37: ANNEX | Y37: LAINE | Z37: B | AG37: =IF(T37>0,CONCATENATE(AA37,AB37,TEXT(AC37,"R00"),TEXT(AD37,"L0."),TEXT(AE37,"0")),"")
A38: =IF(ISBLANK(inbound_data[[#This Row],[Receiving Report ref.'#]]),"",IF(inbound_data[[#This Row],[Ending Quantity]]=0,"ZERO","INV")) -> ZERO | B38: =IF(ISBLANK(D38),"",TEXT(ROW(),"00000")) -> 00038 | C38: =IF(ISBLANK(D38),"",inbound_data[[#This Row],[Pallet_Series]]&inbound_data[[#This Row],[No.]]) -> DUO-00030A/762000038 | D38: 45944 | E38: RECEIVING | F38: 105131 | G38: CALOOCAN | H38: CCK-8782 | I38: 78680 | J38: DUO-00030A/7620 | K38: 1 | L38: ASADO SIOPAO 10'S (1.3 KG) (CHIBAO) | M38: LOCAL TRANSFER | N38: 45931 | O38: 46478 | P38: =IF(A38="ZERO","",IF(O38="","",O38-TODAY())) | Q38: =IF(A38="ZERO","",IF(P38<0,"ALREADY EXPIRED",IF(P38<60,"NEARLY EXPIRED",""))) | R38: 30 | S38: =30*10.4 -> 312 | T38: =IF(ISBLANK(R38),0,R38-SUMIF(STOCK_CODE_OUT,$C38,QTY_OUT)) -> 0 | U38: =IF(ISBLANK(S38),0,S38-SUMIF(STOCK_CODE_OUT,$C38,KILOS_OUT)) -> 0 | V38: =IF(ISBLANK(K38),0,K38-SUMIF(STOCK_CODE_OUT,$C38,PALLET_OUT)) -> 0 | W38: BXS | X38: ANNEX | Y38: LAINE | Z38: R | AG38: =IF(T38>0,CONCATENATE(AA38,AB38,TEXT(AC38,"R00"),TEXT(AD38,"L0."),TEXT(AE38,"0")),"")
A39: =IF(ISBLANK(inbound_data[[#This Row],[Receiving Report ref.'#]]),"",IF(inbound_data[[#This Row],[Ending Quantity]]=0,"ZERO","INV")) -> ZERO | B39: =IF(ISBLANK(D39),"",TEXT(ROW(),"00000")) -> 00039 | C39: =IF(ISBLANK(D39),"",inbound_data[[#This Row],[Pallet_Series]]&inbound_data[[#This Row],[No.]]) -> DUO-00031A/1056800039 | D39: 45944 | E39: RECEIVING | F39: 105131 | G39: CALOOCAN | H39: CCK-8782 | I39: 78680 | J39: DUO-00031A/10568 | K39: 1 | L39: ASADO SIOPAO 10'S (1.3 KG) (CHIBAO) | M39: LOCAL TRANSFER | N39: 45931 | O39: 46478 | P39: =IF(A39="ZERO","",IF(O39="","",O39-TODAY())) | Q39: =IF(A39="ZERO","",IF(P39<0,"ALREADY EXPIRED",IF(P39<60,"NEARLY EXPIRED",""))) | R39: 30 | S39: =30*10.4 -> 312 | T39: =IF(ISBLANK(R39),0,R39-SUMIF(STOCK_CODE_OUT,$C39,QTY_OUT)) -> 0 | U39: =IF(ISBLANK(S39),0,S39-SUMIF(STOCK_CODE_OUT,$C39,KILOS_OUT)) -> 0 | V39: =IF(ISBLANK(K39),0,K39-SUMIF(STOCK_CODE_OUT,$C39,PALLET_OUT)) -> 0 | W39: BXS | X39: ANNEX | Y39: LAINE | Z39: R | AG39: =IF(T39>0,CONCATENATE(AA39,AB39,TEXT(AC39,"R00"),TEXT(AD39,"L0."),TEXT(AE39,"0")),"")
